Workbook

Sheet Items
D2: OH | E2: Cards
B3: 11-100 | C3: Dust Cap, Lubed 1.99 for 2-3.5K axle. Includes plug. GENUINE AXLETEK
B4: 11-105 | C4: Dust Cap, Lubed 2.44 for 5.2-6K axle. Includes plug. GENUINE AXLETEK
B5: 11-110 | C5: Dust Cap, Lubed 2.72 for 7-8K axle. Includes plug. GENUINE AXLETEK
B6: 11-115 | C6: Dust Cap, 1.99 for 2-3.5K axle. GENUINE AXLETEK
B7: 11-120 | C7: Dust Cap, 2.44 for 5.2-6K axle. GENUINE AXLETEK
B8: 11-125 | C8: Dust Cap, 2.72 for 7-8K axle. GENUINE AXLETEK
B9: 11-130 | C9: Dust Cap, replacement rubber plug. GENUINE AXLETEK
B10: 11-850 | C10: Grease Seal Kit 2K 1.25” I.D. GENUINE AXLETEK
B11: 11-855 | C11: Grease Seal Kit 2K 1.50” I.D. GENUINE AXLETEK
B12: 11-860 | C12: Grease Seal Kit 3.5K 1.719” I.D. GENUINE AXLETEK
B13: 11-865 | C13: Grease Seal Kit 5.2-8K 2.25” I.D. GENUINE AXLETEK
B14: 11-870 | C14: Grease Seal Kit 5-8K 2.125” I.D. GENUINE AXLETEK
... B60: 21-895 | C60: Shackle Strap 3.125" hole center PK/4 - GENUINE AXLETEK
B62: 409
B63: 277
B64: 206

Sheet Private Pkg_AxleTek
B1: AFTMKT # | C1: Former AxleTek # Listed for Reference | D1: Category | E1: Sub | F1: Description | G1: QTY Inc | H1: Box/Carton QTY | I1: Pallet QTY | J1: 2025 Confirmed Costs | K1: in catalog
A2: 10 | B2: 10-824 | C2: KBE-363-00 | D2: Brake Part | E2: Spring | F2: GENUINE AXLETEK RETURN SPRING KIT FOR 10 x 2-1/4 and 12 x 2" electric brakes without parking feature | G2: 1 | H2: 30 | I2: 1200 | J2: 0.51
A3: 10 | B3: 10-825 | C3: KBE-353-00 | D3: Brake Part | E3: Clip | F3: GENUINE AXLETEK HOLD-DOWN KIT ELECTRIC BRAKES | G3: 1 | H3: 50 | I3: 2000 | J3: 0.58
A4: 11 | B4: 10-826 | C4: KBE-324-00 | D4: Brake Part | E4: Adjuster Screw | F4: GENUINE AXLETEK BRAKE ADJ SCREW KIT, 10 x 1-1/2", 10 x 2-1/4" hydraulic and electric, and 12 x 2" electric brakes | G4: 1 | H4: 30 | I4: 1200 | J4: 0.59
A5: 11 | B5: 10-827 | C5: KBE-323-00 | D5: Brake Part | E5: Repair Parts | F5: GENUINE AXLETEK BRAKE ADJ SCREW KIT, 7" ELECTRIC BRAKE | G5: 1 | H5: 30 | I5: 1200 | J5: 0.43
A6: 11 | B6: 11-808 | C6: K-14125A/14276 | D6: Hub | E6: Bearings | F6: GENUINE AXLETEK 7K OUTER/INNER BEARING 12" HUB | G6: 1 | H6: 50 | I6: 2000 | J6: 2.28
A7: 11 | B7: 11-811 | C7: K-15123/245 | D7: Hub | E7: Bearings | F7: GENUINE AXLETEK 6K INNER BEARING 15245/15123 | G7: 1 | H7: 50 | I7: 2000 | J7: 2.12
A8: 12 | B8: 11-812 | C8: K-L44649/10 | D8: Hub | E8: Bearings | F8: GENUINE AXLETEK 3.5K BEARING L44610/L44649 | G8: 1 | H8: 80 | I8: 2400 | J8: 1.33
A9: 12 | B9: 11-813 | C9: K-25580/20 | D9: Hub | E9: Bearings | F9: GENUINE AXLETEK 5.2,6,7&8K BEARING 25520/25580 | G9: 1 | H9: 30 | I9: 1200 | J9: 2.65
A10: 12 | B10: 11-814 | C10: K-LM67048/10 | D10: Hub | E10: Bearings | F10: GENUINE AXLETEK INR/OTR BEARNG LM67010/LM67048 | G10: 1 | H10: 80 | I10: 3200 | J10: 1.53
A11: 12 | B11: 11-815 | C11: K-LM68149/11 | D11: Hub | E11: Bearings | F11: GENUINE AXLETEK INR/OTR BEARNG LM68149/11 | G11: 1 | H11: 80 | I11: 3200 | J11: 1.5
A12: 12 | B12: 11-830 | C12: KBE-321-00 | D12: Brake Part | E12: Magnet | F12: GENUINE AXLETEK MAGNET RETAINING CLIPS (3.5K-7.2K Electric Brakes) PAK/10 | G12: 1 | H12: 80 | I12: 3200 | J12: 0.4
A13: 12 | B13: 11-850 | D13: Hub & Drum | E13: Seal | F13: GENUINE AXLETEK Grease Seal Kit 2K 1.25” I.D.
A14: 12 | B14: 11-855 | D14: Hub & Drum | E14: Seal | F14: GENUINE AXLETEK Grease Seal Kit 2K 1.50” I.D.
A15: 12 | B15: 11-860 | D15: Hub & Drum | E15: Seal | F15: GENUINE AXLETEK Grease Seal Kit 3.5K 1.719” I.D.
A16: 12 | B16: 11-865 | D16: Hub & Drum | E16: Seal | F16: GENUINE AXLETEK Grease Seal Kit 5.2-8K 2.25” I.D.
A17: 12 | B17: 11-870 | D17: Hub & Drum | E17: Seal | F17: GENUINE AXLETEK Grease Seal Kit 5-8K 2.125” I.D.
A18: 12 | B18: 11-875 | D18: Hub & Drum | E18: Seal | F18: GENUINE AXLETEK Oil Bath Seal Kit 7-8K 2.25” I.D. 10-63
A19: 12 | B19: 11-880 | D19: Hub & Drum | E19: Seal | F19: GENUINE AXLETEK Oil Bath Seal Kit 10K 2.875” I.D.
A20: 12 | B20: 11-885 | D20: Hub & Drum | E20: Seal | F20: GENUINE AXLETEK Oil Bath Seal Kit RED 10K 2.875” I.D. 10-51
A21: 13 | B21: 11-890 | D21: Hub & Drum | E21: Seal | F21: GENUINE AXLETEK Oil Bath Seal Kit 12K 3.125 I.D. 10-56
A22: 14 | B22: 12-784 | C22: KB10H-42 | D22: Brake Assy | E22: Hydraulic | F22: GENUINE AXLETEK 3.5K 10 X 2 1/4 RH Hydraulic Brake; Uni-Servo; E-Coat - BOXED | G22: 1 | H22: 1 | I22: 144 | J22: 12.36
A23: 15 | B23: 12-785 | C23: KB10H-41 | D23: Brake Assy | E23: Hydraulic | F23: GENUINE AXLETEK 3.5K 10 X 2 1/4 LH Hydraulic Brake; Uni-Servo; E-Coat - BOXED | G23: 1 | H23: 1 | I23: 144 | J23: 12.36
A24: 15 | B24: 12-786 | C24: KB12H-41 | D24: Brake Assy | E24: Hydraulic | F24: GENUINE AXLETEK 7.0K 12 X 2 LH Hydraulic Brake; Uni-Servo; E-Coat - BOXED | G24: 1 | H24: 1 | I24: 108 | J24: 13.92
A25: 15 | B25: 12-787 | C25: KB12H-42 | D25: Brake Assy | E25: Hydraulic | F25: GENUINE AXLETEK 7.0K 12 X 2 RH Hydraulic Brake; Uni-Servo; E-Coat - BOXED | G25: 1 | H25: 1 | I25: 108 | J25: 13.92
A26: 17 | B26: 12-788 | C26: KB7E-02 | D26: Brake Assy | E26: Electric | F26: GENUINE AXLETEK 2.0K 7 X 1 1/4 RH Electric Brake; Std Wire (White) - BOXED | G26: 1 | H26: 1 | I26: 540 | J26: 9.39 | M26: =J26*1.75 -> 16.4325 | N26: =M26/0.75 -> 21.91
A27: 17 | B27: 12-789 | C27: KB7E-01 | D27: Brake Assy | E27: Electric | F27: GENUINE AXLETEK 2.0K 7 X 1 1/4 LH Electric Brake; Std Wire (White) - BOXED | G27: 1 | H27: 1 | I27: 540 | J27: 9.39
A28: 17 | B28: 12-793 | C28: KB10E-01 | D28: Brake Assy | E28: Electric | F28: GENUINE AXLETEK 3.5K 10 X 2 1/4 LH Electric Brake; Std Wire (Green) - BOXED | G28: 1 | H28: 1 | I28: 144 | J28: 10.66
A29: 17 | B29: 12-794 | C29: KB10E-02 | D29: Brake Assy | E29: Electric | F29: GENUINE AXLETEK 3.5K 10 X 2 1/4 RH Electric Brake; Std Wire (Green) - BOXED | G29: 1 | H29: 1 | I29: 144 | J29: 10.66
A30: 17 | B30: 12-795 | C30: KB10EA-21 | D30: Brake Assy | E30: Electric FSA | F30: GENUINE AXLETEK 3.5K 10 X 2 1/4 LH Electric Brake; Self Adjust; Std Wire (Green), Mounting Hdwe - BOXED | G30: 1 | H30: 1 | I30: 144 | J30: 11.67
B31: 12-796 | C31: KB10EA-22 | D31: Brake Assy | E31: Electric FSA | F31: GENUINE AXLETEK 3.5K 10 X 2 1/4 RH Electric Brake; Self Adjust; Std Wire (Green), Mounting Hdwe - BOXED | G31: 1 | H31: 1 | I31: 144 | J31: 11.67
B32: 12-797 | C32: KB12E-01 | D32: Brake Assy | E32: Electric | F32: GENUINE AXLETEK 7.0K 12 X 2 LH Electric Brake; Std Wire (Black) - BOXED | G32: 1 | H32: 1 | I32: 108 | J32: 12.51
B33: 12-798 | C33: KB12E-02 | D33: Brake Assy | E33: Electric | F33: GENUINE AXLETEK 7.0K 12 X 2 RH Electric Brake; Std Wire (Black) - BOXED | G33: 1 | H33: 1 | I33: 108 | J33: 12.51
B34: 12-799 | C34: KB12E-03 | D34: Brake Assy | E34: Electric | F34: GENUINE AXLETEK 6.0K 12 X 2 LH Electric Brake; Std Wire (White) - BOXED | G34: 1 | H34: 1 | I34: 108 | J34: 12.51
B35: 12-800 | C35: KB12E-04 | D35: Brake Assy | E35: Electric | F35: GENUINE AXLETEK 6.0K 12 X 2 RH Electric Brake; Std Wire (White) - BOXED | G35: 1 | H35: 1 | I35: 108 | J35: 12.51
B36: 12-801 | C36: KB12EA-23 | D36: Brake Assy | E36: Electric FSA | F36: GENUINE AXLETEK 6.0K 12 X 2 LH Electric Brake; Self Adjust; Std Wire (White) - BOXED | G36: 1 | H36: 1 | I36: 108 | J36: 13.3
A37: 17 | B37: 12-802 | C37: KB12EA-24 | D37: Brake Assy | E37: Electric FSA | F37: GENUINE AXLETEK 6.0K 12 X 2 RH Electric Brake; Self Adjust; Std Wire (White) - BOXED | G37: 1 | H37: 1 | I37: 108 | J37: 13.3
A38: 17 | B38: 12-803 | C38: KB12EA-21 | D38: Brake Assy | E38: Electric FSA | F38: GENUINE AXLETEK 7.0K 12 X 2 LH Electric Brake; Self Adjust; Std Wire (Black), Mounting Hdwe- BOXED | G38: 1 | H38: 1 | I38: 108 | J38: 13.3
A39: 17 | B39: 12-804 | C39: KB12EA-22 | D39: Brake Assy | E39: Electric FSA | F39: GENUINE AXLETEK 7.0K 12 X 2 RH Electric Brake; Self Adjust; Std Wire (Black), Mounting Hdwe - BOXED | G39: 1 | H39: 1 | I39: 108 | J39: 13.3
A40: 19 | B40: 12-805 | C40: KB10H-73 | D40: Brake Assy | E40: Hydraulic | F40: GENUINE AXLETEK 3.5K 10 X 2 1/4 LH Hydraulic Brake; Free-Backing; Dacromet; AL Cylinder: SS Springs - BOXED | G40: 1 | H40: 1 | I40: 144 | J40: 15.59
...

Sheet BOM_AxleTek
G1: Labor | H1: 0.75
A2: AFTMKT # | B2: Former AxleTek # Listed for Reference | C2: Item # | D2: Parts Included in Kit | E2: Description | F2: GS1 Code | G2: QTY Inc | H2: Cost | I2: 1.15 | J2: Box/Carton QTY | K2: Pallet QTY | L2: 2025 Confirmed Costs | M2: Dealer | N2: Retail | O2: TS Item # | P2: Tractor Supply | Q2: NOTES | R2: SELL | T2: RETAIL | V2: INTERNET
A3: 11-850 | B3: K-DL-125-03 | E3: GENUINE AXLETEK 2K 1.25” I.D. Double Lip Seal PAK/2 DL-125-03 | F3: 810797031398 | G3: 1 | L3: =SUM(I4:I8) -> 2.529 | M3: 4.72 | N3: 8.99 | O3: 1075325 | P3: 24.99 | R3: =L3*1.75 -> 4.42575 | S3: =SUM(R3-L3)/R3 -> 0.42857143 | T3: 6.99 | U3: =SUM(T3-R3)/T3 -> 0.36684549 | V3: 9.7 | W3: =SUM(V3-L3)/V3 -> 0.73927835 | X3: https://www.etrailer.com/Trailer-Bearings-Races-Seals-Caps/TruRyde/RG06-010.html
A4: 12-892 | B4: DL-125-03 | C4: 12-892 | D4: 2) Grease Seal 1.25" ID (DL-125-03) | G4: 2 | H4: =VLOOKUP(C4,Inventory!A:L,12,FALSE) -> 0.28 | I4: =SUM(H4*$I$2)*G4 -> 0.644
A5: RG06-010 | B5: 206TF | C5: 206TF | D5: Clam | G5: 1 | H5: =VLOOKUP(C5,Inventory!A:L,12,FALSE) -> 0.6 | I5: =H5*G5 -> 0.6
C6: 206LABEL | D6: Label | G6: 1 | H6: =VLOOKUP(C6,Inventory!A:L,12,FALSE) -> 0.31 | I6: =H6*G6 -> 0.31
C7: LABOR75 | D7: Labor | G7: 1 | H7: =VLOOKUP(C7,Inventory!A:L,12,FALSE) -> 0.75 | I7: =H7*G7 -> 0.75
D8: Box | G8: 0.25 | H8: 0.9 | I8: =H8*G8 -> 0.225
A10: 11-855 | B10: K-DL-150-03 | E10: GENUINE AXLETEK 2K 1.50” I.D. Double Lip Seal PAK/2 DL-150-03 | F10: 810797031404 | G10: 1 | L10: =SUM(I11:I15) -> 2.529 | M10: 4.72 | N10: 8.99 | R10: =L10*1.75 -> 4.42575 | S10: =SUM(R10-L10)/R10 -> 0.42857143 | T10: 6.99 | U10: =SUM(T10-R10)/T10 -> 0.36684549 | V10: 6.95 | W10: =SUM(V10-L10)/V10 -> 0.63611511 | X10: https://www.etrailer.com/Trailer-Bearings-Races-Seals-Caps/TruRyde/RG06-020.html
A11: 12-860 | B11: DL-150-03 | C11: 12-860 | D11: 2) Grease Seal 1.50" ID (DL-150-03) | G11: 2 | H11: =VLOOKUP(C11,Inventory!A:L,12,FALSE) -> 0.28 | I11: =SUM(H11*$I$2)*G11 -> 0.644 | V11: 8.95 | X11: https://www.lippert.com/lippert-double-lip-grease-seal-2200-lb-brake-idler-hub-assemblies-15in-id-2-pack-2023134653-2023134653?queryID=094563ed1bc9f91f4fc64f2d35287416&objectID=23851&indexName=gwp_d2c_prod_lippert_products
C12: 206TF | D12: Clam | G12: 1 | H12: =VLOOKUP(C12,Inventory!A:L,12,FALSE) -> 0.6 | I12: =H12*G12 -> 0.6
A13: 2023134653 | C13: 206LABEL | D13: Label | G13: 1 | H13: =VLOOKUP(C13,Inventory!A:L,12,FALSE) -> 0.31 | I13: =H13*G13 -> 0.31
A14: RG06-020 | B14: 206TF | C14: LABOR75 | D14: Labor | G14: 1 | H14: =VLOOKUP(C14,Inventory!A:L,12,FALSE) -> 0.75 | I14: =H14*G14 -> 0.75
D15: Box | G15: 0.25 | H15: 0.9 | I15: =H15*G15 -> 0.225
A17: 11-860 | B17: K-DL-172-03 | E17: GENUINE AXLETEK 3.5K 1.719” I.D. Double Lip Seal, PAK/2 DL-172-03 | F17: 810797031411 | G17: 1 | J17: 30 | K17: 1200 | L17: =SUM(I18:I22) -> 2.736 | M17: 4.98 | N17: 9.99 | O17: 1075325 | P17: 24.99 | R17: =L17*1.75 -> 4.788 | S17: =SUM(R17-L17)/R17 -> 0.42857143 | T17: 7.49 | U17: =SUM(T17-R17)/T17 -> 0.36074766 | V17: 7.94 | W17: =SUM(V17-L17)/V17 -> 0.65541562 | X17: https://www.etrailer.com/Trailer-Bearings-Races-Seals-Caps/etrailer/RG06-050.html
A18: 14-828 | B18: DL-172-03 | C18: 12-819 | D18: 2) Grease Seal 1.72" ID (DL-172-03) | G18: 2 | H18: =VLOOKUP(C18,Inventory!A:L,12,FALSE) -> 0.37 | I18: =SUM(H18*$I$2)*G18 -> 0.851 | V18: 8.95 | X18: https://www.lippert.com/lippert-double-lip-grease-seal-3500-to-4400-lb-axles-1719in-id-2-pack-2023134654-2023134654?queryID=5b645c1f2c321dab7e318b7b47656f51&objectID=23853&indexName=gwp_d2c_prod_lippert_products
C19: 206TF | D19: Clam | G19: 1 | H19: =VLOOKUP(C19,Inventory!A:L,12,FALSE) -> 0.6 | I19: =H19*G19 -> 0.6
A20: 2023134654 | C20: 206LABEL | D20: Label | G20: 1 | H20: =VLOOKUP(C20,Inventory!A:L,12,FALSE) -> 0.31 | I20: =H20*G20 -> 0.31
A21: RG06-050 | B21: 206TF | C21: LABOR75 | D21: Labor | G21: 1 | H21: =VLOOKUP(C21,Inventory!A:L,12,FALSE) -> 0.75 | I21: =H21*G21 -> 0.75
D22: Box | G22: 0.25 | H22: 0.9 | I22: =H22*G22 -> 0.225
A24: 11-865 | B24: K-DL-225-03 | E24: GENUINE AXLETEK 5.2-8K 2.25” I.D. Double Lip Seal, PAK/2 DL-225-03 | F24: 810797031428 | G24: 1 | J24: 30 | K24: 1200 | L24: =SUM(I25:I29) -> 3.023 | M24: 5.52 | N24: 10.99 | R24: =L24*1.75 -> 5.29025 | S24: =SUM(R24-L24)/R24 -> 0.42857143 | T24: 7.99 | U24: =SUM(T24-R24)/T24 -> 0.33789111 | V24: 8.34 | W24: =SUM(V24-L24)/V24 -> 0.63752998 | X24: https://www.etrailer.com/Trailer-Bearings-Races-Seals-Caps/TruRyde/RG06-070.html
A25: 14-829 | B25: DL-225-03 | C25: 12-836 | D25: 2) Grease Seal 2.25" ID (DL-225-03) | G25: 2 | H25: =VLOOKUP(C25,Inventory!A:L,12,FALSE) -> 0.46 | I25: =SUM(H25*$I$2)*G25 -> 1.058 | V25: 9.95 | X25: https://www.lippert.com/lippert-double-lip-grease-seal-5200-to-8000-lb-axles-225in-id-2-pack-2023134655-2023134655?queryID=02a41a9c6576b2786b6248520e4c0ac2&objectID=23852&indexName=gwp_d2c_prod_lippert_products
C26: 277TF | D26: Clam | G26: 1 | H26: =VLOOKUP(C26,Inventory!A:L,12,FALSE) -> 0.69 | I26: =H26*G26 -> 0.69
A27: 2023134655 | C27: 277LABEL | D27: Label | G27: 1 | H27: =VLOOKUP(C27,Inventory!A:L,12,FALSE) -> 0.3 | I27: =H27*G27 -> 0.3
A28: RG06-070 | B28: change | C28: LABOR75 | D28: Labor | G28: 1 | H28: =VLOOKUP(C28,Inventory!A:L,12,FALSE) -> 0.75 | I28: =H28*G28 -> 0.75
D29: Box | E29: u-bolt kit | G29: 0.25 | H29: 0.9 | I29: =H29*G29 -> 0.225
A31: 11-870 | B31: K-DL-2125-03 | E31: GENUINE AXLETEK 7-8K 2.125” I.D. Double Lip Seal, PAK/2 DL-2125-03 | F31: 810797031435 | L31: =SUM(I32:I36) -> 1.965 | M31: 5.52 | N31: 10.99 | R31: =L31*1.75 -> 3.43875 | S31: =SUM(R31-L31)/R31 -> 0.42857143 | T31: 7.99 | U31: =SUM(T31-R31)/T31 -> 0.56961827 | V31: 22.03 | W31: =SUM(V31-L31)/V31 -> 0.91080345 | X31: https://www.etrailer.com/Trailer-Bearings-Races-Seals-Caps/TruRyde/RG06-090.html
A32: 12-810 | B32: DL-2125-03 | C32: 12-837 | D32: 2) Grease Seal 2.15" ID (DL-2125-03) | G32: 2 | H32: 0 | I32: =SUM(H32*$I$2)*G32 -> 0
C33: 277TF | D33: Clam | G33: 1 | H33: =VLOOKUP(C33,Inventory!A:L,12,FALSE) -> 0.69 | I33: =H33*G33 -> 0.69
C34: 277LABEL | D34: Label | G34: 1 | H34: =VLOOKUP(C34,Inventory!A:L,12,FALSE) -> 0.3 | I34: =H34*G34 -> 0.3
A35: RG06-090 | B35: 206TF | C35: LABOR75 | D35: Labor | G35: 1 | H35: =VLOOKUP(C35,Inventory!A:L,12,FALSE) -> 0.75 | I35: =H35*G35 -> 0.75
D36: Box | G36: 0.25 | H36: 0.9 | I36: =H36*G36 -> 0.225
A39: 11-875 | B39: K-OB-1063-01 | E39: GENUINE AXLETEK 7-8K 2.25” I.D. Unitized Oil Seal, PAK/2 OB-1063-01 | F39: 810797031442 | L39: =SUM(I40:I44) -> 22.8674 | N39: 44.99 | Q39: eTrailer BULK price for 1 | R39: =L39*1.75 -> 40.01795 | S39: =SUM(R39-L39)/R39 -> 0.42857143 | T39: 49.99 | U39: =SUM(T39-R39)/T39 -> 0.1994809 | V39: 68.85 | W39: =SUM(V39-L39)/V39 -> 0.66786638 | X39: https://www.etrailer.com/Trailer-Bearings-Races-Seals-Caps/Dexter/10-63.html
A40: 12-863 | C40: 12-863 | D40: 2) Oil Seal 2.25" ID (OB-1063-01) | G40: 2 | H40: 7.36 | I40: =SUM(H40*1.42)*G40 -> 20.9024 | V40: 25.95 | X40: https://www.lippert.com/lippert-shaft-oil-seal-5200-8000-lb-axles-225in-id-2-pack-2023134018-2023134018?queryID=d842bd848a12a72931ba35b2812807da&objectID=23891&indexName=gwp_d2c_prod_lippert_products
A41: 10-63 | C41: 277TF | D41: Clam | G41: 1 | H41: =VLOOKUP(C41,Inventory!A:L,12,FALSE) -> 0.69 | I41: =H41*G41 -> 0.69
A42: 2023134018 | C42: 277LABEL | D42: Label | G42: 1 | H42: =VLOOKUP(C42,Inventory!A:L,12,FALSE) -> 0.3 | I42: =H42*G42 -> 0.3
C43: LABOR75 | D43: Labor | G43: 1 | H43: =VLOOKUP(C43,Inventory!A:L,12,FALSE) -> 0.75 | I43: =H43*G43 -> 0.75
D44: Box | G44: 0.25 | H44: 0.9 | I44: =H44*G44 -> 0.225
A46: 11-880 | B46: K-OB-183463 | E46: GENUINE AXLETEK 10K 2.875” I.D. Unitized Oil BLUE Seal, PAK/2 OB-183463 | F46: 810797031459 | G46: 1 | L46: =SUM(I47:I51) -> 24.4294 | N46: 49.99 | Q46: eTrailer BULK price for 1 | R46: =L46*1.75 -> 42.75145 | S46: =SUM(R46-L46)/R46 -> 0.42857143 | T46: 52.99 | U46: =SUM(T46-R46)/T46 -> 0.19321664 | V46: 59.99 | W46: =SUM(V46-L46)/V46 -> 0.59277546
A47: 12-851 | C47: 12-851 | D47: 2) Oil Seal 2.875" ID (OB-183463) | G47: 2 | H47: 7.91 | I47: =SUM(H47*1.42)*G47 -> 22.4644 | V47: 24.95 | X47: https://www.lippert.com/lippert-wheel-end-oil-seal-10000-lb-axles-2875in-id-2-pack-2023134019-2023134019?queryID=100e4c514cd30761a75f2c3f087ba47b&objectID=23850&indexName=gwp_d2c_prod_lippert_products
...

Sheet Private Pkg_TowPro
B1: AFTMKT # | C1: Former AxleTek # Listed for Reference | D1: Category | E1: Sub | F1: Description | G1: QTY Inc | H1: Box/Carton QTY | I1: Pallet QTY | J1: 2025 Confirmed Costs
B3: 40-115 | D3: Jack | E3: Hardware | F3: TowPro Jack Pin, 9/16" x 3-1/2", replacement pin for 40-321, 322, 323 & 325 Jacks
B4: 40-120 | D4: Jack | E4: Hardware | F4: TowPro Jack Pin, 5/8" x 4", replacement pin for 40-354, 356, 357 & 358 Jacks
B5: 40-125 | D5: Jack | E5: Hardware | F5: TowPro Jack Pin, 9/16" x 2-3/4", replacement pin for 40-451, 452 & 453 Jacks
B7: 50-101 | D7: Coupler | E7: Hardware | F7: TowPro Pin for Sleeve Lock Couplers. 5/16" x 2-3/4" Usable Length
B9: 10-900 | D9: Brake | E9: Actuation | F9: TowPro Breakaway Kit w/ LED Test Light, Side Load, Includes Battery Box, Battery, Switch, Charger and Wire Leads
B10: 10-950 | D10: Brake | E10: Actuation | F10: TowPro Breakaway Switch with Cable
B11: 10-951 | D11: Brake | E11: Actuation | F11: TowPro Breakaway Replacement Pin & Cable
B12: 10-980 | D12: Brake | E12: Actuation | F12: TowPro Breakaway Battery 12v 5A
B14: 60-500 | D14: Towing | E14: Locks | F14: TowPro 1/4 Inch Black Trailer Hitch Coupler Lock
B15: 60-501 | D15: Towing | E15: Locks | F15: TowPro 5/8 Inch x 3 inch Black Trailer Hitch Pin and Clip With Grooved Head
B16: 60-502 | D16: Towing | E16: Locks | F16: TowPro 5/8 Inch x 3.5 inch Black Trailer Hitch Pin and Clip With Grooved Head
B17: 60-503 | D17: Towing | E17: Locks | F17: TowPro 5/8 Inch Black Trailer Hitch Receiver Bent Pin Lock
... B20: 60-506 | D20: Towing | E20: Locks | F20: TowPro Heavy Duty Anti-Theft Universal Black Trailer Hitch Tow Ball Coupler Security Kit

Sheet Private Label_TowPro
B1: AFTMKT # | C1: Former AxleTek # Listed for Reference | D1: Category | E1: Sub | F1: Pin | G1: Collar | H1: Description | I1: QTY Inc | J1: Box/Carton QTY | K1: Pallet QTY | L1: 2025 Confirmed Costs | M1: catalog
B2: 50-275 | C2: CTA-400 | D2: Couplers | E2: Adjustable | H2: TowPro Coupler, Adjustable, 2-5/16" ball size, 14000# capacity, black powder coat finish, w/ bolts and nuts | J2: 250 | K2: 20 | L2: 7.4
B3: 50-280 | C3: CTA-196 | D3: Couplers | E3: Adjustable | H3: TowPro Coupler, Adjustable, collar style, 2" ball size, 7000# capacity, black powder coat finish, w/bolts and nuts | J3: 150 | K3: 20 | L3: 10
B4: 50-281 | C4: CTA-296 | D4: Couplers | E4: Adjustable | H4: TowPro Coupler, Adjustable, collar style, 2-5/16" ball size, 12500# capacity, black powder coat finish, w/bolts and nuts | J4: 150 | K4: 20 | L4: 12
B5: 50-285 | C5: CTA-280 | D5: Couplers | E5: Adjustable | H5: TowPro Coupler, Adjustable, heavy duty cast construction, 2-5/16" ball size, 15000# capacity, black powder coat finish, w/bolts and nuts | J5: 200 | K5: 16 | L5: 17.5
B6: 50-300 | C6: CTA-CB4 | D6: Couplers | E6: Adjustable | H6: TowPro 3 position channel bracket for Adjustable coupler | J6: 400 | K6: 20 | L6: 2.2
B7: 50-301 | C7: CTA-CB6 | D7: Couplers | E7: Adjustable | H7: TowPro 5 position channel bracket for Adjustable coupler | J7: 250 | K7: 20 | L7: 2.8
B8: 50-302 | C8: CTA-CB126 | D8: Couplers | E8: Adjustable | H8: TowPro 5 position HD 1/2" channel bracket for Adjustable coupler | J8: 250 | K8: 18 | L8: 4.1
B9: 50-900 | C9: MBT58500-LN58 | D9: Couplers | E9: Adjustable | H9: TowPro Coupler Bolt, Grade 8 bolt/nut for adjustable couplers, size=5/8", length=5.0" | J9: 2000 | K9: 18 | L9: 0.8
B10: 40-200 | C10: TJA-2000-B | D10: Jacks | E10: A-Frame | H10: TowPro Jack, A-frame 2,000 lb, top wind, black | J10: 220 | K10: 20 | L10: 5.3
B11: 40-201 | C11: TJA-5000-B | D11: Jacks | E11: A-Frame | H11: TowPro Jack, A-frame 5,000 lb, top wind, black | J11: 220 | K11: 20 | L11: 6.5
B12: 40-035 | C12: JSP-100 | D12: Jacks | E12: A-Frame | H12: TowPro Jack, Support Plate for 2-1/4" OD A-Frame TowPro Jacks | J12: 3000 | K12: 20 | L12: 0.36
B13: 40-453 | C13: TJDA-8000 | D13: Jacks | E13: A-Frame | F13: TJD-7000-PN | H13: TowPro Jack, A-frame mini-drop leg TowPro Jack, Top Wind, 8000# supprt cap., 8000# lift capacity, 28.5" travel, black finish | J13: 150 | K13: 12 | L13: 16.5
B14: 50-201 | C14: CA-5100-B | D14: Couplers | E14: A-Frame | H14: TowPro A-Frame coupler, 2" ball size, 5000#, black painted | J14: 250 | K14: 20 | L14: 4.1
B15: 50-205 | C15: CA-5400-O | D15: Couplers | E15: A-Frame | H15: TowPro A-Frame coupler, 2-5/16" ball size, 14,000#, OILY | J15: 250 | K15: 20 | L15: 5
B16: 50-206 | C16: CA-5400-B | D16: Couplers | E16: A-Frame | H16: TowPro A-Frame coupler, 2-5/16" ball size, 14,000#, BLACK | J16: 250 | K16: 20 | L16: 5.4
B17: 50-210 | C17: CA-5210-B | D17: Couplers | E17: A-Frame | H17: TowPro A-Frame coupler, 2" ball size, 8000# capacity w/ wrap-around helmet, black | J17: 220 | K17: 20 | L17: 5.4
B18: 50-215 | C18: CA-5196-B | D18: Couplers | E18: A-Frame | H18: TowPro A-Frame coupler, Collar Style, 2" ball, 7000# capacity | J18: 150 | K18: 20 | L18: 12.7
B19: 50-225 | C19: CA-5296-B | D19: Couplers | E19: A-Frame | H19: TowPro Coupler, A-Frame coupler, Colar Style, 2-5/16" ball, 12500# capacity | J19: 125 | K19: 19 | L19: 15.5
B20: 60-001 | D20: Towing | E20: Ball Mount | H20: TowPro Ball Mount with 2" Ball (2" Shank, 7,500 lbs., 2" Drop) | J20: 180 | L20: 5.8
B21: 60-002 | D21: Towing | E21: Ball Mount | H21: TowPro Ball Mount with 2" Ball (2" Shank, 7,500 lbs., 4" Drop) | J21: 180 | L21: 6.7
B22: 60-003 | D22: Towing | E22: Ball Mount | H22: TowPro Ball Mount with 2-5/16" Ball (2" Shank, 7,500 lbs., 2" Drop) | J22: 180 | L22: 6.3
B23: 60-004 | D23: Towing | E23: Ball Mount | H23: TowPro Ball Mount with 2-5/16" Ball (2" Shank, 7,500 lbs., 4" Drop) | J23: 180 | L23: 7.3
B24: 60-100 | D24: Towing | E24: Ball Mount | H24: TowPro Reducer Sleeve Set (3" to 2-1/2" to 2" Shanks, 2 Pieces) | J24: 288 | L24: 4.1
B25: 60-101 | D25: Towing | E25: Ball Mount | H25: TowPro Reducer Sleeve Set (2-1/2" to 2" Shank) | J25: 216 | L25: 4
B26: 60-020 | D26: Towing | E26: Ball Mount | H26: TowPro Forged Ball Mount with 2-5/16" Ball (2-1/2" Shank, 20,000 lbs, 4" Drop) | J26: 90 | L26: 16.5
B27: 60-200 | D27: Towing | E27: Ball Mount | H27: TowPro Adjustable Trailer Hitch Ball Mount with Dual Ball, 2-1/2" Shank, 20K | J27: 45 | L27: 33
B28: 60-205 | D28: Towing | E28: Ball Mount | H28: TowPro Ball Mount Adjustable Aluminum Hitch with Dual Ball, 5-1/2" Drop (2" Shank 10,000 lbs) | J28: 72 | L28: 42
B29: 60-210 | D29: Towing | E29: Ball Mount | H29: TowPro Ball Mount Adjustable Aluminum Hitch with Dual Ball, 5-1/2" Drop (2" Shank 12,500 lbs) | J29: 60 | L29: 27
B30: 40-451 | C30: TJD-7000 | D30: Jacks | E30: Drop Leg | F30: TJD-7000-PN | H30: TowPro Jack, Drop Leg HD, Top Wind, 2.5" Square TowPro Jack, 8000# support capacity, 7000# lift capacity | J30: 100 | K30: 20 | L30: 14
B31: 40-452 | C31: TJD-7000S | D31: Jacks | E31: Drop Leg | F31: TJD-7000-PN | H31: TowPro Jack, Drop Leg HD, Side Wind, 2.5" Square TowPro Jack, 8000# support capacity, 7000# lift capacity | J31: 100 | K31: 20 | L31: 16
B32: 40-412 | C32: TJD-12000SP-F2 | D32: Jacks | E32: Drop Leg | F32: TJD-12000-PPN | H32: TowPro Jack, Heavy Duty Square, Front Pin, 12000# support capacity, 10,000# lift capacity, w / spring return, handle and handle clip | J32: 30 | K32: 20 | L32: 44.5
B33: 40-414 | C33: TJD-12000SP-R2 | D33: Jacks | E33: Drop Leg | F33: TJD-12000-PPN | H33: TowPro Jack, Heavy Duty Square, Side Pin, 12000# support capacity, 10,000# lift capacity, w / spring return, handle and handle clip | J33: 30 | K33: 20 | L33: 44.5
B34: 40-413 | C34: TJD-12000SP-F2NH | D34: Jacks | E34: Drop Leg | F34: TJD-12000-PPN | H34: TowPro Jack, Heavy Duty Square, Front Pin, 12000# support capacity, 10,000# lift capacity, w / spring return, NO HANDLE | J34: 30 | K34: 20 | L34: 44
B35: 40-415 | C35: TJD-12000SP-R2NH | D35: Jacks | E35: Drop Leg | F35: TJD-12000-PPN | H35: TowPro Jack, Heavy Duty Square, Side Pin, 12000# support capacity, 10,000# lift capacity, w / spring return, NO HANDLE | J35: 30 | K35: 20 | L35: 44
B36: 40-416 | C36: TJD-12000TWSP-R | D36: Jacks | E36: Drop Leg | F36: TJD-12000-PPN | H36: TowPro Heavy duty square jack, top wind, 12,000# support capacity, 10000# lift cap.,w/spring return, handle and handle clip, side pin | J36: 30 | K36: 20 | L36: 40
B37: 50-520 | C37: GCPN-25008 | D37: Couplers | E37: Gooseneck | H37: TowPro Coupler, Round GN, 25000# capacity, cast cone-shaped head, ¾” load bearing pin, 8” adjustment. | J37: 30 | K37: 20 | L37: 37
B38: 50-521 | C38: GCPN-30008 | D38: Couplers | E38: Gooseneck | H38: TowPro Coupler, Round GN, 30000# capacity, ¾” load bearing pin, 8” adjustment, head with cast cone-shaped bottom and forged steel one-piece top plate | J38: 30 | K38: 20 | L38: 41
B39: 50-525 | C39: GPSQ-25008 | D39: Couplers | E39: Gooseneck | H39: TowPro Square gooseneck coupler, 4.5" square tube, 25000# capacity, cast cone-shaped head, 3/4" load bearing pin, 8" adjustment | J39: 30 | K39: 20 | L39: 39
B40: 50-526 | C40: GCSQ-30008 | D40: Couplers | E40: Gooseneck | H40: TowPro Square gooseneck coupler, 4.5" square tube, 30000# capacity, cast cone-shaped head, 3/4" load bearing pin, 8" adjustment | J40: 30 | K40: 20 | L40: 46
...

Sheet Master Data
A2: TowParts | B2: AxleTek Part Number | C2: Industry Ref | D2: Vendor | E2: Vendor Item # | F2: Category | G2: Sub Category | H2: Type | I2: Desc | K2: Wt (lb) | L2: Wt (kg) | M2: Pallet Qty | O2: Package Qty | P2: ProAxle Landed
B3: H-545-97 | C3: 84545XG | D3: Jiaodong | E3: H-545-97 | F3: Hub & Drum | G3: Hub - Pregreased Kit | H3: Bulk | I3: Hub Kit 3.5K 5 on 4.5" Pre-Greased EZ (Boxed - BULK). L44649 / L68149 bearing 1.72 Seal - GALVANIZED | K3: 8.14 | L3: 3.6922798 | M3: 240 | O3: 1
B4: H-545-09 | C4: 84545XG | D4: Jiaodong | E4: H-545-09 | F4: Hub & Drum | G4: Hub - Pregreased Kit | H4: Bulk | I4: Hub Kit 3.5K 5 on 4.5" Pre-Greased EZ (Boxed - BULK). L44649 / L68149 bearing 1.72 Seal | K4: 8.14 | L4: 3.6922798 | M4: 240 | O4: 1
B5: H-550-07 | C5: 84545XG | D5: Jiaodong | E5: H-550-07 | F5: Hub & Drum | G5: Hub - Pregreased Kit | H5: Bulk | I5: Hub Kit 3.5K 5 on 5.50" Pre-Greased EZ (Boxed - BULK). L44649 / L68149 bearing 1.72 Seal | K5: 8.14 | L5: 3.6922798 | M5: 240 | O5: 1
B6: H-655 | C6: 42656XG | D6: Jiaodong | E6: H-655 | F6: Hub & Drum | G6: Hub - Pregreased Kit | H6: Bulk | I6: Hub Kit 6.0K 6 on 5.5" Pre-Greased EZ (Boxed - BULK) 15123 / 25580 Bearing 2.25 seal | K6: 15.48 | L6: 7.0216819 | M6: 140 | O6: 1
B7: BD3-545 | C7: 84546XG | D7: Jiaodong | E7: BD3-545 | F7: Hub & Drum | G7: Hub/Drum - Pregreased Kit | H7: Bulk | I7: Hub & Drum Kit 3.5K 5 on 4.5" Pre-Greased EZ (Boxed - BULK). L44649 / L68149 bearing 1.72 Seal | K7: 20.94 | L7: 9.4983217 | M7: 72 | O7: 1
B8: BD3-550 | C8: 8K865OK | D8: Jiaodong | E8: BD3-550 | F8: Hub & Drum | G8: Hub/Drum - Pregreased Kit | H8: Bulk | I8: Hub & Drum Kit 3.5K 5 on 5.0" Pre-Greased EZ (Boxed - BULK). L44649 / L68149 bearing 1.72 Seal | K8: 20.94 | L8: 9.4983217 | M8: 72 | O8: 1
B9: BD3-65535 | C9: 84656XG | D9: Jiaodong | E9: BD3-65535 | F9: Hub & Drum | G9: Hub/Drum - Pregreased Kit | H9: Bulk | I9: Hub & Drum Kit 3.5K 6 on 5.5" Pre-Greased EZ (Boxed - BULK). L44649 / L68149 bearing 1.72 Seal | L9: 9.4027778 | M9: 72 | O9: 1
B10: BD3-655 | C10: 42656XG | D10: Jiaodong | E10: BD3-655 | F10: Hub & Drum | G10: Hub/Drum - Pregreased Kit | H10: Bulk | I10: Hub & Drum Kit 6.0K 6 on 5.5" Pre-Greased EZ (Boxed - BULK). 15123 / 25580 Bearing, 2.25 seal | K10: 32.36 | L10: 14.6784 | M10: 45 | O10: 1
B11: BD3-865 | C11: 42866XG | D11: Jiaodong | E11: BD3-865 | F11: Hub & Drum | G11: Hub/Drum - Pregreased Kit | H11: Bulk | I11: Hub & Drum kit 7.K 8 on 6.5" Pre-Greased EZ (Boxed - BULK). 14125A / 25580 bearing 1/2" Studs 2.25 Seal | K11: 35.35 | L11: 16.034655 | M11: 45 | O11: 1
B12: BD3-865-916 | C12: 42866XG916 | D12: Jiaodong | E12: BD3-865-916 | F12: Hub & Drum | G12: Hub/Drum - Pregreased Kit | H12: Bulk | I12: Hub & Drum kit 7K 8 on 6.5" Pre-Greased EZ (Boxed - BULK). 14125A / 25580 bearing 9/16" Studs 2.25 Seal | K12: 35.7 | L12: 16.193414 | M12: 45 | O12: 1
A13: 17-310 | D13: Jiaodong | F13: Hub & Drum | G13: Hub - Pregreased Kit | H13: Package Program | I13: HUB 3.5K, 5-4.50 Pre-Greased Kit, L44649 / L68149 Bearings, 1.72" Seal, Lube Dust Cap & Plug, Wheel Nuts, Hdwe, GALVANIZED - GENUINE AXLETEK, Boxed | J13: #VALUE! | L13: 3.875 | M13: 240 | N13: 1 | O13: 1
A14: 17-335 | D14: Jiaodong | F14: Hub & Drum | G14: Hub - Pregreased Kit | H14: Package Program | I14: HUB 6K, 6-5.50 Pre-Greased Kit, 15123 / 25580 Bearings, 2.25 Seal, Lube Dust Cap & Plug, Wheel Nuts, Hdwe, GALVANIZED - GENUINE AXLETEK, Boxed | L14: 8.2053571
A15: 17-340 | D15: Jiaodong | F15: Hub & Drum | G15: Hub - Pregreased Kit | H15: Package Program | I15: HUB 7K 8-6.50 Pre-Greased Kit, 14125A / 25580 Bearings, 2.25 Seal, Lube Dust Cap & Plug, Wheel Nuts, Hdwe, GALVANIZED - GENUINE AXLETEK, Boxed | L15: 8.3583333
A16: 17-110 | D16: Jiaodong | E16: 17-110 | F16: Hub & Drum | G16: Hub - Pregreased Kit | H16: Package Program | I16: HUB 3.5K, 5-4.50 Pre-Greased Kit, L44649 / L68149 Bearings, 1.72" Seal, Lube Dust Cap & Plug, Wheel Nuts, Hdwe, GENUINE AXLETEK, Boxed | J16: #VALUE! | L16: 3.875 | M16: 240 | N16: 1 | O16: 1
A17: 17-115 | D17: Jiaodong | E17: 17-115 | F17: Hub & Drum | G17: Hub - Pregreased Kit | H17: Package Program | I17: HUB 3.5K, 5-5.0 Pre-Greased Kit, L44649 / L68149 Bearings, 1.72" Seal, Lube Dust Cap & Plug, Wheel Nuts, Hdwe, GENUINE AXLETEK, Boxed | L17: 3.875 | M17: 240 | N17: 1 | O17: 1
A18: 17-130 | D18: Jiaodong | E18: 17-130 | F18: Hub & Drum | G18: Hub - Pregreased Kit | H18: Package Program | I18: HUB 3.5K, 6-5.0 Pre-Greased Kit, L44649 / L68149 Bearings, 1.72" Seal, Lube Dust Cap & Plug, Wheel Nuts, Hdwe, GENUINE AXLETEK, Boxed | L18: 4.552381 | M18: 210 | N18: 1 | O18: 1
A19: 17-135 | D19: Jiaodong | E19: 17-135 | F19: Hub & Drum | G19: Hub - Pregreased Kit | H19: Package Program | I19: HUB 6K, 6-5.50 Pre-Greased Kit, 15123 / 25580 Bearings, 2.25 Seal, Lube Dust Cap & Plug, Wheel Nuts, Hdwe, GENUINE AXLETEK, Boxed | L19: 8.2053571 | M19: 140 | N19: 1 | O19: 1
A20: 17-140 | D20: Jiaodong | E20: 17-140 | F20: Hub & Drum | G20: Hub - Pregreased Kit | H20: Package Program | I20: HUB 7K 8-6.50 Pre-Greased Kit, 14125A / 25580 Bearings, 2.25 Seal, Lube Dust Cap & Plug, Wheel Nuts, Hdwe, GENUINE AXLETEK, Boxed | L20: 8.3583333 | M20: 120 | N20: 1 | O20: 1
A21: 19-100 | D21: Jiaodong | E21: 19-100 | F21: Hub & Drum | G21: Hub/Drum - Pregreased Kit | H21: Package Program | I21: HUB & DRUM 3.5K, 5-4.50 Pre-Greased Kit, L44649 / L68149 Bearings, 1.72" Seal, Lube Dust Cap & Plug, Wheel Nuts, Hdwe, GENUINE AXLETEK, Boxed | L21: 9.6527778 | M21: 72 | N21: 1 | O21: 1
A22: 19-110 | D22: Jiaodong | E22: 19-110 | F22: Hub & Drum | G22: Hub/Drum - Pregreased Kit | H22: Package Program | I22: HUB & DRUM 3.5K, 5-5.0 Pre-Greased Kit, L44649 / L68149 Bearings, 1.72" Seal, Lube Dust Cap & Plug, Wheel Nuts, Hdwe, GENUINE AXLETEK, Boxed | L22: 9.6527778 | M22: 72 | N22: 1 | O22: 1
A23: 19-120 | D23: Jiaodong | E23: 19-120 | F23: Hub & Drum | G23: Hub/Drum - Pregreased Kit | H23: Package Program | I23: HUB & DRUM 3.5K, 6-5.0 Pre-Greased Kit, L44649 / L68149 Bearings, 1.72" Seal, Lube Dust Cap & Plug, Wheel Nuts, Hdwe, GENUINE AXLETEK, Boxed | L23: 9.4027778 | M23: 72 | N23: 1 | O23: 1
A24: 19-125 | D24: Jiaodong | E24: 19-125 | F24: Hub & Drum | G24: Hub/Drum - Pregreased Kit | H24: Package Program | I24: HUB & DRUM 6K, 6-5.50 Pre-Greased Kit, 15123 / 25580 Bearings, 2.25 Seal, Lube Dust Cap & Plug, Wheel Nuts, Hdwe, GENUINE AXLETEK, Boxed | L24: 12.911111 | M24: 45 | N24: 1 | O24: 1
A25: 19-130 | D25: Jiaodong | E25: 19-130 | F25: Hub & Drum | G25: Hub/Drum - Pregreased Kit | H25: Package Program | I25: HUB & DRUM 7K 8-6.50, 1/2" Studs Pre-Greased Kit, 14125A / 25580 Bearings, 2.25 Seal, Lube Dust Cap & Plug, Wheel Nuts, Hdwe, GENUINE AXLETEK, Boxed | K25: 33.5 | L25: 14.977778 | M25: 45 | N25: 1 | O25: 1
A26: 19-135 | D26: Jiaodong | E26: 19-135 | F26: Hub & Drum | G26: Hub/Drum - Pregreased Kit | H26: Package Program | I26: HUB & DRUM 7K 8-6.50, 9/16" Studs Pre-Greased Kit, 14125A / 25580 Bearings, 2.25 Seal, Lube Dust Cap & Plug, Wheel Nuts, Hdwe, GENUINE AXLETEK, Boxed | L26: 15.022222 | M26: 45 | N26: 1 | O26: 1
A27: 11-008 | B27: BD-86580-36 | D27: Jiaodong | E27: BD-86580-26 | F27: Hub & Drum | G27: Hub/Drum - Only | H27: Bulk | I27: Hub & Drum, 8K 8 on 6.5", 9/16" studs, Oil bath, uses 02475 / 25580 bearing & 10-63 Seal, GENUINE AXLETEK | J27: #VALUE! | K27: 53.95 | L27: 24.444444 | M27: 36 | N27: 1 | O27: 1
A28: 11-009 | B28: BD-86580-56 | C28: 8K865O | D28: Jiaodong | E28: BD-86580-46 | F28: Hub & Drum | G28: Hub/Drum - Only | H28: Bulk | I28: Hub & Drum, 8K 8 on 6.5", 5/8" studs, Oil bath, uses 02475 / 25580 bearing & 10-63 Seal, GENUINE AXLETEK | K28: 54.16 | L28: 24.722222 | M28: 36 | N28: 1 | O28: 1
A29: 11-010 | B29: 008-430-05 | C29: 10K865HD | D29: Jiaodong | E29: 008-430-05 | F29: Hub & Drum | G29: Hub/Drum - Only | H29: Bulk | I29: Hub & Drum Assembly 10K GD, 4.75" Pilot, uses 387A / 25580 bearings, 10-51 seal & 4" Oil Cap. 008-430DX (After 4/2013) GENUINE AXLETEK | J29: #VALUE! | K29: 60.04 | L29: 28.777778 | M29: 36 | N29: 1 | O29: 1
A30: 11-011 | B30: 008-430-03 | C30: 10K865H | D30: Jiaodong | E30: 008-430-03 | F30: Hub & Drum | G30: Hub - Only | H30: Bulk | I30: Hub 10K GD, 4.75" Pilot, uses 387A / 25580 bearings, 10-51 seal & 4" Oil Cap. 008-430DX (After 4/2013) GENUINE AXLETEK | L30: 11 | M30: 100 | N30: 1 | O30: 1
A31: 11-023 | B31: 9-123 | C31: 10K865D | D31: Jiaodong | E31: 9-123 | F31: Hub & Drum | G31: Drum | H31: Bulk | I31: Drum Only, 10K GD, 9-123DX (After 4/2013) GENUINE AXLETEK | L31: 17.166667 | M31: 36 | N31: 1 | O31: 1
A32: 11-012 | B32: BD-86512 | C32: 12K865HD | D32: Jiaodong | E32: BD-86512 | F32: Hub & Drum | G32: Hub/Drum - Only | H32: Bulk | I32: Hub & Drum Assembly 12K, uses 3984 / 28682 bearings, 10-56 seal, & 4" Oil Cap. 8-214DX, GENUINE AXLETEK | J32: #VALUE! | K32: 76.88 | L32: 43.5 | M32: 24 | N32: 1 | O32: 1
A33: 11-013 | B33: 821407 | C33: 12K865H | D33: Jiaodong | E33: 821407 | F33: Hub & Drum | G33: Hub - Only | H33: Bulk | I33: Hub 12K, uses 3984 / 28682 bearings, 10-56 seal, & 4" Oil Cap. 8-214DX, GENUINE AXLETEK | L33: 12.1 | M33: 60 | N33: 1 | O33: 1
A34: 11-028 | B34: 902801 | C34: 12K865D | D34: Jiaodong | E34: 902801 | F34: Hub & Drum | G34: Drum | H34: Bulk | I34: Drum Olny, 12K, 9-28DX GENUINE AXLETEK | L34: 1.4590643 | M34: 36 | N34: 1 | O34: 1
A35: 12-026 | B35: B10E-21 | D35: Weifang Airui | E35: B10E-21 | F35: Brakes | G35: Brake | H35: Bulk | I35: Brake Electric 10" x 2-1/4" for 3,500-lb axles LH (Driver) | M35: 168 | O35: 1
A36: 12-027 | B36: B10E-22 | D36: Weifang Airui | E36: B10E-22 | F36: Brakes | G36: Brake | H36: Bulk | I36: Brake Electric 10" x 2-1/4" for 3,500-lb axles RH (Passanger) | M36: 168 | O36: 1
A37: 12-180 | B37: B12E-21 | D37: Weifang Airui | E37: B12E-21 | F37: Brakes | G37: Brake | H37: Bulk | I37: Brake Electric 12" x 2" for 6-7,000 lb axles LH (Driver) | M37: 126 | O37: 1
A38: 12-181 | B38: B12E-22 | D38: Weifang Airui | E38: B12E-22 | F38: Brakes | G38: Brake | H38: Bulk | I38: Brake Electric 12" x 2" for 6-7,000 lb axles RH (Passanger) | M38: 126 | O38: 1
A39: 12-468 | B39: B10EA-21 | D39: Weifang Airui | E39: B10EA-21 | F39: Brakes | G39: Brake | H39: Bulk | I39: Brake Electric 10" x 2-1/4" for 3,500-lb axles, Left Hand Self Adjusting EB-10LSA | J39: #VALUE! | K39: 9.88 | L39: =K39/2.2046 -> 4.4815386 | M39: 168 | O39: 1
A40: 12-469 | B40: B10EA-22 | D40: Weifang Airui | E40: B10EA-22 | F40: Brakes | G40: Brake | H40: Bulk | I40: Brake Electric 10" x 2-1/4" for 3,500-lb axles, Right Hand Self Adjusting EB-10RSA | K40: 9.88 | L40: =K40/2.2046 -> 4.4815386 | M40: 168 | O40: 1
A41: 12-464 | B41: B12EA-21 | D41: Weifang Airui | E41: B12EA-21 | F41: Brakes | G41: Brake | H41: Bulk | I41: Brake Electric 12" x 2" for 6-7,000 lb axles, Left Hand Self Adjusting EB-12LSA | K41: 14.75 | L41: =K41/2.2046 -> 6.6905561 | M41: 126 | O41: 1
...

Sheet GS1
A1: Part # | B1: Description | C1: UPC | D1: Confirmed FOB Asia Cost from Peter MARK
A2: 10-824 | B2: GENUINE AXLETEK RETURN SPRING KIT FOR 10 x 2-1/4 and 12 x 2" electric brakes without parking feature | C2: 810797030025
A3: 10-825 | B3: GENUINE AXLETEK HOLD-DOWN KIT ELECTRIC BRAKES | C3: 810797030001
A4: 10-826 | B4: GENUINE AXLETEK BRAKE ADJ SCREW KIT, 10 x 1-1/2", 10 x 2-1/4" hydraulic and electric, and 12 x 2" electric brakes | C4: 810797030032
A5: 10-827 | B5: GENUINE AXLETEK BRAKE ADJ SCREW KIT, 7" ELECTRIC BRAKE | C5: 810797030049
A6: 11-808 | B6: GENUINE AXLETEK 7K OUTER/INNER BEARING 12" HUB | C6: 810797030094
A7: 11-811 | B7: GENUINE AXLETEK 6K INNER BEARING 15245/15123 | C7: 810797030100
A8: 11-812 | B8: GENUINE AXLETEK 3.5K BEARING L44610/L44649 | C8: 810797030117
A9: 11-813 | B9: GENUINE AXLETEK 5.2,6,7&8K BEARING 25520/25580 | C9: 810797030124
A10: 11-814 | B10: GENUINE AXLETEK INR/OTR BEARNG LM67010/LM67048 | C10: 810797030131
A11: 11-815 | B11: GENUINE AXLETEK INR/OTR BEARNG LM68149/11 | C11: 810797030148
A12: 11-830 | B12: GENUINE AXLETEK MAGNET RETAINING CLIPS (3.5K-7.2K Electric Brakes) PAK/10 | C12: 810797030155
A13: 12-784 | B13: GENUINE AXLETEK 3.5K 10 X 2 1/4 RH Hydraulic Brake; Uni-Servo; E-Coat - BOXED | C13: 810797030247
... A53: 13-819 | B53: GENUINE AXLETEK 12" MAGNET KIT (5.2K-7K) BRAKE | C53: 810797030087
A54: 14-828 | B54: GENUINE AXLETEK GREASE SEALS, PAK/2 DL-172-03 | C54: 810797030018 | E54: will move to 11-860
A55: 14-829 | B55: GENUINE AXLETEK GREASE SEALS, PAK/2 DL-225-03 | C55: 810797030056 | E55: will move to 11-865
A56: 15-816 | B56: GENUINE AXLETEK ELECTRIC BRAKE SHOE/LINING KIT FOR 7" (2K) BRAKE | C56: 810797030186
A57: 15-820 | B57: GENUINE AXLETEK ELECTRIC BRAKE SHOE/LINING KIT FOR 5.2K-7K BRAKE | C57: 810797030179
A58: 15-821 | B58: GENUINE AXLETEK ELECTRIC BRAKE SHOE/LINING KIT FOR 10" (3.5K) | C58: 810797030162
A59: 15-822 | B59: GENUINE AXLETEK 3.5K 10 X 2 1/4 Hydraulic BRAKE SHOE KIT 10" HYD | C59: 810797030193
A60: 15-823 | B60: GENUINE AXLETEK 7.0K 12 X 2 RH Hydraulic Brake SHOE KIT 12" HYD | C60: 810797030209
A61: 17-100 | B61: GENUINE AXLETEK IDLER HUB 4-4.00 BC 2000# Kit, Bearings, Seal, Lube Dust Cap & Plug, Wheel Nuts, Hdwe, Pre-Greased - Boxed | C61: 810797030681
A62: 17-170 | B62: GENUINE AXLETEK IDLER HUB 4-4.40 BC 2000# Kit, BT8 1" Spindle, Bearings, Seal, Lube Dust Cap & Plug, Wheel Nuts, Wheel Nuts, Hdwe, Pre-Greased - Boxed | C62: 810797030971
A63: 17-175 | B63: GENUINE AXLETEK IDLER HUB 4-4.40 BC 2000# Kit, BTR 1-1/16" Spindle, Bearings, Seal, Lube Dust Cap & Plug, Wheel Nuts, Hdwe, Pre-Greased - Boxed | C63: 810797030988
A64: 17-105 | B64: GENUINE AXLETEK IDLER HUB 5-4.50 BC 2000# Kit, Bearings, Seal, Lube Dust Cap & Plug, Wheel Nuts, Hdwe, use with 8-12" Wheels, Pre-Greased - Boxed | C64: 810797030704
A65: 17-145 | B65: GENUINE AXLETEK IDLER HUB 5-4.50 BC 2000# Kit, BT8 1" Spindle, Bearings, Seal, Lube Dust Cap & Plug, Wheel Nuts, Hdwe, use with 8-12" Wheels, Pre-Greased - Boxed | C65: 810797030902
A66: 17-150 | B66: GENUINE AXLETEK IDLER HUB 5-4.50 BC 2000# Kit, BTR 1-1/16" Spindle, Bearings, Seal, Lube Dust Cap & Plug, Wheel Nuts, Hdwe, use with 8-12" Wheels, Pre-Greased - Boxed | C66: 810797030933
A67: 17-155 | B67: GENUINE AXLETEK IDLER HUB 5-4.50 BC 2000# Kit, 6-1/2" Flange, Bearings, Seal, Lube Dust Cap & Plug, Wheel Nuts, Hdwe, use with 13" to 15" Wheels, Pre-Greased - Boxed | C67: 810797030940
... A106: 21-206 | B106: GENUINE AXLETEK Hanger Kit, Tandem for 1.75" Double Eye Springs (3.5-7K Axle) 6 ea - 2.5" TCH hangers - APT9 | C106: 810797031282
A107: 21-207 | B107: GENUINE AXLETEK Hanger Kit, Triple for 2.00" Slipper Springs 4" Hangers E4541 (5.2-8K Axle) APTT6SE | C107: 810797031299 | D107: SAME AS 21-205
A108: 21-300 | B108: GENUINE AXLETEK Hanger Kit, Single for 2.50" Slipper Springs (10KGD Axle) - HAP158 | C108: 810797031305
A109: 21-305 | B109: GENUINE AXLETEK Hanger Kit, Tandem Add-on for 2.50" Slipper Springs, (10KGD Axle) use with 21-300, 42 1/4" axle spacing - HAP25802 | C109: 810797031312
A110: 21-310 | B110: GENUINE AXLETEK Hanger Kit, Tandem Add-on for 2.50" Slipper Springs, (10KGD Axle) use with 21-300, 48 1/2" axle spacing - HAP25803 | C110: 810797031329
A111: 21-315 | B111: GENUINE AXLETEK Hanger Kit, Single for 3.00" Slipper Springs (12K Axle) - HAP103 | C111: 810797031336
A112: 21-320 | B112: GENUINE AXLETEK Hanger Kit, Tandem Add-on for 3.00" Slipper Springs, (12K Axle) use with 21-315, 42 1/4" axle spacing - HAP20302 | C112: 810797031343
A113: 21-325 | B113: GENUINE AXLETEK Hanger Kit, Tandem Add-on for 3.00" Slipper Springs, (12K Axle) use with 21-315, 48 1/2" axle spacing - HAP20303 | C113: 810797031350
A114: 21-500 | B114: GENUINE AXLETEK Suspension Repair Kit. Includes 2.625 Shackle Straps, 3" Bolt w/ nut & E1 Cast Equalizer. For 1.75” Double Eye Springs | C114: 810797031367
A115: 21-501 | B115: GENUINE AXLETEK Suspension Repair Kit. Includes 3.125 Shackle Straps, 3" Bolt w/ nut & E1 Cast Equalizer. For 1.75” Double Eye Springs | C115: 810797031374
A116: 21-515 | B116: GENUINE AXLETEK Suspension Repair Kit. Includes 12” Equalizer (Black Powder Coat) & hardware. For 2” Slipper Springs | C116: 810797031381
A117: 11-850 | B117: GENUINE AXLETEK Grease Seal Kit 2K 1.25” I.D. | C117: 810797031398
...

Sheet Clam Shells
A1: Clamshell | B1: Card Size | C1: Cavity Size | D1: Link
A2: 409TF | B2: Length F = 7.125" / Width H = 4.343" | C2: Length C = 5.563" / Width D = 3.188" / Depth E = 1.625" | D2: https://store.visipak.com/stock-clamshell-packaging-409tf/
A3: 206TF | B3: Length F = 6.437" / Width H = 3.140" | C3: Length C = 4.688" / Width D = 2.313" / Depth E = 1.313" | D3: https://store.visipak.com/stock-clamshell-packaging-206tf/?srsltid=AfmBOooK8x7Avml7jQVBwErgrG-hUranuU7G8_7DSXT9UBCDzP70u69P
A4: 277TF | B4: Length F = 5.750" / Width H = 4.343" | C4: Length C = 4.250" / Width D = 3.875" / Depth E = 2.000" | D4: https://store.visipak.com/stock-clamshell-packaging-277tf/?srsltid=AfmBOoqfP7aE_9MlJeYegbhhhKFUhyNstFDiD1wbY6c5_FLvwsFwgREJ

Sheet Inventory
A2: TowParts | B2: Desc | C2: Wt (lb) | D2: Wt (kg) | E2: Pallet Qty | F2: On Hand | G2: Date | H2: Vendor | I2: PO | J2: Qty | K2: Est $ Landed | L2: Actual $ Landed | M2: Diff | N2: ETA | O2: Date | P2: Vendor | Q2: PO | R2: Qty | S2: Est $ Landed | T2: ETA | U2: Date | V2: Vendor | W2: PO | X2: Qty | Y2: ETA | Z2: Date | AA2: Vendor | AB2: PO | AC2: Qty | AD2: ETA
B3: Hub 3.5K 5 on 4.5" Pre-Greased , L44649 / L68149 bearing 1.72 Seal - GALVANIZED | C3: 8.14 | D3: 3.6922798
B4: Hub 3.5K 5 on 4.5" Pre-Greased , L44649 / L68149 bearing 1.72 Seal | C4: 8.14 | D4: 3.6922798
B5: Hub 3.5K 5 on 5.50" Pre-Greased , L44649 / L68149 bearing 1.72 Seal | C5: 8.14 | D5: 3.6922798
B6: Hub 6.0K 6 on 5.5" Pre-Greased EZ (Boxed - BULK) 15123 / 25580 Bearing 2.25 seal | C6: 15.48 | D6: 7.0216819
B7: Hub & Drum 3.5K 5 on 4.5" Pre-Greased EZ (BULK). L44649 / L68149 bearing 1.72 Seal | C7: 20.94 | D7: 9.4983217
B8: Hub & Drum 3.5K 5 on 5.0" Pre-Greased EZ (Boxed - BULK). L44649 / L68149 bearing 1.72 Seal | C8: 20.94 | D8: 9.4983217 | F8: ?
B9: Hub & Drum 3.5K 6 on 5.5" Pre-Greased , L44649 / L68149 bearing 1.72 Seal | D9: 9.4027778
B10: Hub & Drum 6.0K 6 on 5.5" Pre-Greased , 15123 / 25580 Bearing, 2.25 seal | C10: 32.36 | D10: 14.6784
B11: Hub & Drum 7.K 8 on 6.5" Pre-Greased , 14125A / 25580 bearing 1/2" Studs 2.25 Seal | C11: 35.35 | D11: 16.034655
B12: Hub & Drum 7K 8 on 6.5" Pre-Greased , 14125A / 25580 bearing 9/16" Studs 2.25 Seal | C12: 35.7 | D12: 16.193414
A13: 17-310 | B13: HUB 3.5K, 5-4.50 Pre-Greased Kit, L44649 / L68149 Bearings, 1.72" Seal, Lube Dust Cap & Plug, Wheel Nuts, Hdwe, GALVANIZED - GENUINE AXLETEK, Boxed | D13: 3.875 | E13: =VLOOKUP(A13,'[1]Master Data'!A:AB,18,FALSE) -> 0 | K13: 16.78 | O13: 45837 | P13: Jiaodong | Q13: 25-12587 | R13: 240 | S13: 16.78 | T13: =O13+90 -> 45927
A14: 17-335 | B14: HUB 6K, 6-5.50 Pre-Greased Kit, 15123 / 25580 Bearings, 2.25 Seal, Lube Dust Cap & Plug, Wheel Nuts, Hdwe, GALVANIZED - GENUINE AXLETEK, Boxed | D14: 8.2053571 | E14: =VLOOKUP(A14,'[1]Master Data'!A:AB,18,FALSE) -> 0 | K14: 28.18 | O14: 45837 | P14: Jiaodong | Q14: 25-12587 | R14: 140 | S14: 28.18 | T14: =O14+90 -> 45927
A15: 17-340 | B15: HUB 7K 8-6.50 Pre-Greased Kit, 14125A / 25580 Bearings, 2.25 Seal, Lube Dust Cap & Plug, Wheel Nuts, Hdwe, GALVANIZED - GENUINE AXLETEK, Boxed | D15: 8.3583333 | E15: =VLOOKUP(A15,'[1]Master Data'!A:AB,18,FALSE) -> 0 | K15: 34.92 | O15: 45837 | P15: Jiaodong | Q15: 25-12587 | R15: 120 | S15: 34.92 | T15: =O15+90 -> 45927
A16: 17-170 | B16: HUB 1K, 4-4.00 Pre-Greased Kit, BT8, L44643 Bearings, 1.25" Seal, Lube Dust Cap & Plug, Wheel Nuts, Hdwe, GENUINE AXLETEK, Boxed
A17: 17-175 | B17: HUB 2K, 4-4.00 Pre-Greased Kit, BTR, L44649 Bearings, 1.50" Seal, Lube Dust Cap & Plug, Wheel Nuts, Hdwe, GENUINE AXLETEK, Boxed
A18: 17-145 | B18: HUB 1K, 5-4.50 Pre-Greased Kit, BT8 5-1/2" Flange, L44643 Bearings, 1.25" Seal, Lube Dust Cap & Plug, Wheel Nuts, Hdwe, 5.5 for 8-12" Wheel, GENUINE AXLETEK, Boxed | D18: 70
A19: 17-150 | B19: HUB 2K, 5-4.50 Pre-Greased Kit, BTR 5-1/2" Flange, L44649 Bearings, 1.50" Seal, Lube Dust Cap & Plug, Wheel Nuts, Hdwe, 5.5 for 8-12" Wheel, GENUINE AXLETEK, Boxed | D19: 70
A20: 17-160 | B20: HUB 1K, 5-4.50 Pre-Greased Kit, BT8 6-1/2" Flange, L44643 Bearings, 1.25" Seal, Lube Dust Cap & Plug, Wheel Nuts, Hdwe, 6.5 Flange 13-15" Wheel, GENUINE AXLETEK, Boxed | D20: 70 | O20: 45837 | P20: Jiaodong | Q20: 25-12587 | R20: 70 | T20: =O20+90 -> 45927
A21: 17-165 | B21: HUB 2K, 5-4.50 Pre-Greased Kit, BTR 6-1/2" Flange, L44649 Bearings, 1.50" Seal, Lube Dust Cap & Plug, Wheel Nuts, Hdwe, 6.5 Flange 13-15" Wheel, GENUINE AXLETEK, Boxed | D21: 70 | O21: 45837 | P21: Jiaodong | Q21: 25-12587 | R21: 140 | T21: =O21+90 -> 45927
A22: 17-110 | B22: HUB 3.5K, 5-4.50 Pre-Greased Kit, L44649 / L68149 Bearings, 1.72" Seal, Lube Dust Cap & Plug, Wheel Nuts, Hdwe, GENUINE AXLETEK, Boxed | D22: 3.875 | E22: =VLOOKUP(A22,'[1]Master Data'!A:AB,18,FALSE) -> 0 | G22: 45775 | H22: Jiaodong | I22: 25-12353 | J22: 240 | K22: 13.39 | L22: 16.39 | M22: =SUM(L22-K22)/L22 -> 0.18303844 | N22: =G22+90 -> 45865 | O22: 45837 | P22: Jiaodong | Q22: 25-12587 | R22: 240 | S22: 13.39 | T22: =O22+90 -> 45927
A23: 17-115 | B23: HUB 3.5K, 5-5.00 Pre-Greased Kit, L44649 / L68149 Bearings, 1.72" Seal, Lube Dust Cap & Plug, Wheel Nuts, Hdwe, GENUINE AXLETEK, Boxed | D23: 3.875 | E23: =VLOOKUP(A23,'[1]Master Data'!A:AB,18,FALSE) -> 0 | K23: 13.39 | O23: 45837 | P23: Jiaodong | Q23: 25-12587 | R23: 240 | S23: 13.39 | T23: =O23+90 -> 45927
A24: 17-130 | B24: HUB 3.5K, 6-5.50 Pre-Greased Kit, L44649 / L68149 Bearings, 1.72" Seal, Lube Dust Cap & Plug, Wheel Nuts, Hdwe, GENUINE AXLETEK, Boxed | D24: 4.552381 | E24: =VLOOKUP(A24,'[1]Master Data'!A:AB,18,FALSE) -> 0 | K24: 15.01 | O24: 45837 | P24: Jiaodong | Q24: 25-12587 | R24: 210 | S24: 15.01 | T24: =O24+90 -> 45927
A25: 17-135 | B25: HUB 6K, 6-5.50 Pre-Greased Kit, 15123 / 25580 Bearings, 2.25 Seal, Lube Dust Cap & Plug, Wheel Nuts, Hdwe, GENUINE AXLETEK, Boxed | D25: 8.2053571 | E25: =VLOOKUP(A25,'[1]Master Data'!A:AB,18,FALSE) -> 0 | G25: 45775 | H25: Jiaodong | I25: 25-12353 | J25: 140 | K25: 22.38898 | L25: 27.3 | M25: =SUM(L25-K25)/L25 -> 0.17989084 | N25: =G25+90 -> 45865 | O25: 45837 | P25: Jiaodong | Q25: 25-12587 | R25: 140 | S25: 22.39 | T25: =O25+90 -> 45927
A26: 17-140 | B26: HUB 7K 8-6.50 Pre-Greased Kit, 14125A / 25580 Bearings, 2.25 Seal, Lube Dust Cap & Plug, Wheel Nuts, Hdwe, GENUINE AXLETEK, Boxed | D26: 8.3583333 | E26: =VLOOKUP(A26,'[1]Master Data'!A:AB,18,FALSE) -> 0 | G26: 45775 | H26: Jiaodong | I26: 25-12353 | J26: 120 | K26: 27.322715 | L26: 33.29 | M26: =SUM(L26-K26)/L26 -> 0.17925156 | N26: =G26+90 -> 45865
A27: 19-100 | B27: HUB & DRUM 3.5K, 5-4.50 Pre-Greased Kit, L44649 / L68149 Bearings, 1.72" Seal, Lube Dust Cap & Plug, Wheel Nuts, Hdwe, GENUINE AXLETEK, Boxed | D27: 9.6527778 | E27: =VLOOKUP(A27,'[1]Master Data'!A:AB,18,FALSE) -> 0 | G27: 45775 | H27: Jiaodong | I27: 25-12353 | J27: 144 | K27: 24.987241 | L27: 27.63 | M27: =SUM(L27-K27)/L27 -> 0.095648168 | N27: =G27+90 -> 45865 | O27: 45837 | P27: Jiaodong | Q27: 25-12587 | R27: 72 | S27: 24.99 | T27: =O27+90 -> 45927
A28: 19-110 | B28: HUB & DRUM 3.5K, 5-5.00 Pre-Greased Kit, L44649 / L68149 Bearings, 1.72" Seal, Lube Dust Cap & Plug, Wheel Nuts, Hdwe, GENUINE AXLETEK, Boxed | D28: 9.6527778 | E28: =VLOOKUP(A28,'[1]Master Data'!A:AB,18,FALSE) -> 0 | K28: 24.987241 | O28: 45837 | P28: Jiaodong | Q28: 25-12587 | R28: 72 | S28: 24.99 | T28: =O28+90 -> 45927
A29: 19-120 | B29: HUB & DRUM 3.5K, 6-5.50 Pre-Greased Kit, L44649 / L68149 Bearings, 1.72" Seal, Lube Dust Cap & Plug, Wheel Nuts, Hdwe, GENUINE AXLETEK, Boxed | D29: 9.4027778 | E29: =VLOOKUP(A29,'[1]Master Data'!A:AB,18,FALSE) -> 0 | K29: 27.263881 | O29: 45837 | P29: Jiaodong | Q29: 25-12587 | R29: 72 | S29: 27.26 | T29: =O29+90 -> 45927
A30: 19-125 | B30: HUB & DRUM 6K, 6-5.50 Pre-Greased Kit, 15123 / 25580 Bearings, 2.25 Seal, Lube Dust Cap & Plug, Wheel Nuts, Hdwe, GENUINE AXLETEK, Boxed | D30: 12.911111 | E30: =VLOOKUP(A30,'[1]Master Data'!A:AB,18,FALSE) -> 0 | G30: 45775 | H30: Jiaodong | I30: 25-12353 | J30: 70 | K30: 37.990688 | L30: 41.47 | M30: =SUM(L30-K30)/L30 -> 0.083899499 | N30: =G30+90 -> 45865 | O30: 45837 | P30: Jiaodong | Q30: 25-12587 | R30: 45 | S30: 37.99 | T30: =O30+90 -> 45927
A31: 19-130 | B31: HUB & DRUM 7K 8-6.50, 1/2" Studs Pre-Greased Kit, 14125A / 25580 Bearings, 2.25 Seal, Lube Dust Cap & Plug, Wheel Nuts, Hdwe, GENUINE AXLETEK, Boxed | C31: 33.5 | D31: 14.977778 | E31: =VLOOKUP(A31,'[1]Master Data'!A:AB,18,FALSE) -> 0 | G31: 45775 | H31: Jiaodong | I31: 25-12353 | J31: 140 | K31: 41.263358 | L31: 45.97 | M31: =SUM(L31-K31)/L31 -> 0.10238508 | N31: =G31+90 -> 45865 | O31: 45837 | P31: Jiaodong | Q31: 25-12587 | R31: 90 | S31: 41.26 | T31: =O31+90 -> 45927
A32: 19-135 | B32: HUB & DRUM 7K 8-6.50, 9/16" Studs Pre-Greased Kit, 14125A / 25580 Bearings, 2.25 Seal, Lube Dust Cap & Plug, Wheel Nuts, Hdwe, GENUINE AXLETEK, Boxed | D32: 15.022222 | E32: =VLOOKUP(A32,'[1]Master Data'!A:AB,18,FALSE) -> 0 | G32: 45775 | H32: Jiaodong | I32: 25-12353 | J32: 185 | K32: 41.927378 | L32: 46.88 | M32: =SUM(L32-K32)/L32 -> 0.10564467 | N32: =G32+90 -> 45865 | O32: 45837 | P32: Jiaodong | Q32: 25-12587 | R32: 45 | S32: 41.93 | T32: =O32+90 -> 45927
A33: 11-008 | B33: Hub & Drum, 8K 8 on 6.50, 9/16" studs, Oil bath, uses 02475 / 25580 bearing & 2.25 Seal, GENUINE AXLETEK | C33: 53.95 | D33: 24.444444 | E33: =VLOOKUP(A33,'[1]Master Data'!A:AB,18,FALSE) -> 0 | K33: 49.754664 | O33: 45837 | P33: Jiaodong | Q33: 25-12587 | R33: 20 | S33: 49.75 | T33: =O33+90 -> 45927
A34: 11-007 | B34: Hub & Drum, 8K 8 on 6.5", 5/8" studs, Grease, uses 02475 / 25580 bearing & 2.25 Seal, GENUINE AXLETEK | E34: 36 | K34: 50 | O34: 45837 | P34: Jiaodong | Q34: 25-12587 | R34: 36 | S34: 50.01 | T34: =O34+90 -> 45927
A35: 11-009 | B35: Hub & Drum, 8K 8 on 6.5", 5/8" studs, Oil bath, uses 02475 / 25580 bearing & 2.25 Seal, GENUINE AXLETEK | C35: 54.16 | D35: 24.722222 | E35: =VLOOKUP(A35,'[1]Master Data'!A:AB,18,FALSE) -> 0 | G35: 45775 | H35: Jiaodong | I35: 25-12353 | J35: 108 | K35: 50.260584 | L35: 56.86 | M35: =SUM(L35-K35)/L35 -> 0.1160643 | N35: =G35+90 -> 45865
A36: 11-010 | B36: Hub & Drum Assembly 10K GD, 4.75" Pilot, uses 387A / 25580 bearings, 10-51 seal & 4" Oil Cap. 008-430DX (After 4/2013) GENUINE AXLETEK | C36: 60.04 | D36: 28.777778 | E36: =VLOOKUP(A36,'[1]Master Data'!A:AB,18,FALSE) -> 0 | G36: 45775 | H36: Jiaodong | I36: 25-12353 | J36: 144 | K36: 72.540519 | L36: 84.75 | M36: =SUM(L36-K36)/L36 -> 0.14406467 | N36: =G36+90 -> 45865 | O36: 45837 | P36: Jiaodong | Q36: 25-12587 | R36: 36 | S36: 72.54 | T36: =O36+90 -> 45927
A37: 11-011 | B37: Hub 10K GD, 4.75" Pilot, uses 387A / 25580 bearings, 10-51 seal & 4" Oil Cap. 008-430DX (After 4/2013) GENUINE AXLETEK | D37: 11 | E37: =VLOOKUP(A37,'[1]Master Data'!A:AB,18,FALSE) -> 0 | G37: 45775 | H37: Jiaodong | I37: 25-12353 | J37: 100 | K37: 30.488727 | L37: 36.2 | M37: =SUM(L37-K37)/L37 -> 0.15776997 | N37: =G37+90 -> 45865 | O37: 45837 | P37: Jiaodong | Q37: 25-12587 | R37: 100 | S37: 30.49 | T37: =O37+90 -> 45927
A38: 11-023 | B38: Drum Only, 10K GD, 9-123DX (After 4/2013) GENUINE AXLETEK | D38: 17.166667 | E38: =VLOOKUP(A38,'[1]Master Data'!A:AB,18,FALSE) -> 0 | G38: 45775 | H38: Jiaodong | I38: 25-12353 | J38: 36 | K38: 41.848451 | L38: 48.55 | M38: =SUM(L38-K38)/L38 -> 0.13803396 | N38: =G38+90 -> 45865
A39: 11-012 | B39: Hub & Drum Assembly 12K, uses 3984 / 28682 bearings, 10-56 seal, & 4" Oil Cap. 8-214DX, GENUINE AXLETEK | C39: 76.88 | D39: 43.5 | E39: =VLOOKUP(A39,'[1]Master Data'!A:AB,18,FALSE) -> 0 | G39: 45775 | H39: Jiaodong | I39: 25-12353 | J39: 24 | K39: 94.953314 | L39: 108.1 | M39: =SUM(L39-K39)/L39 -> 0.12161597 | N39: =G39+90 -> 45865
A40: 11-013 | B40: Hub 12K, uses 3984 / 28682 bearings, 10-56 seal, & 4" Oil Cap. 8-214DX, GENUINE AXLETEK | D40: 12.1 | E40: =VLOOKUP(A40,'[1]Master Data'!A:AB,18,FALSE) -> 0 | K40: 34.58 | O40: 45837 | P40: Jiaodong | Q40: 25-12587 | R40: 60 | S40: 34.58 | T40: =O40+90 -> 45927
A41: 11-028 | B41: Drum Olny, 12K, 9-28DX GENUINE AXLETEK | D41: 1.4590643 | E41: =VLOOKUP(A41,'[1]Master Data'!A:AB,18,FALSE) -> 0
...

Sheet BOM_AxleTekA
B1: =TODAY() -> 46259 | C1: Winnsboro, Texas | L1: Labor | M1: 0.75
A2: AFTMKT # | B2: On Hand | C2: On Order | D2: Weekly Sales | E2: WOS OH | F2: Last 12 | G2: Former AxleTek # Listed for Reference | H2: Item # | I2: Parts Included in Kit | J2: Description | K2: GS1 Code | L2: QTY Inc | M2: Cost | N2: 1.15 | O2: Box/Carton QTY | P2: Pallet QTY | Q2: 2025 Confirmed Costs | R2: Dealer | S2: Retail | T2: TS Item # | U2: Tractor Supply | V2: NOTES | W2: SELL | Y2: RETAIL | AA2: INTERNET
A3: 11-850 | B3: =IFERROR(VLOOKUP($H3,'QB Inv Curr'!$H:$AD,13,FALSE),"") -> 0 | C3: =IFERROR(VLOOKUP($H3,'QB Inv Curr'!$H:$AE,23,FALSE),"") -> 0 | D3: =IFERROR(VLOOKUP($H3,'QB Inv Curr'!$H:$AL,29,FALSE),"") -> 0 | F3: =IFERROR(SUM(D3*12),"") -> 0 | G3: K-DL-125-03 | H3: 11-850 | J3: GENUINE AXLETEK 2K 1.25” I.D. Double Lip Seal PAK/2 DL-125-03 | K3: 810797031398 | L3: 1 | Q3: =SUM(N4:N8) -> 2.529 | R3: 4.72 | S3: 8.99 | T3: 1075325 | U3: 24.99 | W3: =Q3*1.75 -> 4.42575 | X3: =SUM(W3-Q3)/W3 -> 0.42857143 | Y3: 6.99 | Z3: =SUM(Y3-W3)/Y3 -> 0.36684549 | AA3: 9.7 | AB3: =SUM(AA3-Q3)/AA3 -> 0.73927835 | AC3: https://www.etrailer.com/Trailer-Bearings-Races-Seals-Caps/TruRyde/RG06-010.html
A4: 12-892 | B4: =IFERROR(VLOOKUP($H4,'QB Inv Curr'!$H:$AD,13,FALSE),"") -> 1000 | C4: =IFERROR(VLOOKUP($H4,'QB Inv Curr'!$H:$AE,23,FALSE),"") -> 0 | D4: =IFERROR(VLOOKUP($H4,'QB Inv Curr'!$H:$AL,29,FALSE),"") -> 0 | E4: =IFERROR(SUM(B4/D4),"") | F4: =IFERROR(SUM(D4*12),"") -> 0 | G4: DL-125-03 | H4: 12-892 | I4: 2) Grease Seal 1.25" ID (DL-125-03) | L4: 2 | M4: =VLOOKUP(H4,Inventory!A:L,12,FALSE) -> 0.28 | N4: =SUM(M4*$N$2)*L4 -> 0.644
A5: RG06-010 | B5: =IFERROR(VLOOKUP($H5,'QB Inv Curr'!$H:$AD,13,FALSE),"") -> 880 | C5: =IFERROR(VLOOKUP($H5,'QB Inv Curr'!$H:$AE,23,FALSE),"") -> 0 | D5: =IFERROR(VLOOKUP($H5,'QB Inv Curr'!$H:$AL,29,FALSE),"") -> 0 | E5: =IFERROR(SUM(B5/D5),"") | F5: =IFERROR(SUM(D5*12),"") -> 0 | G5: 206TF | H5: 206TF | I5: Clam | L5: 1 | M5: =VLOOKUP(H5,Inventory!A:L,12,FALSE) -> 0.6 | N5: =M5*L5 -> 0.6
B6: =IFERROR(VLOOKUP($H6,'QB Inv Curr'!$H:$AD,13,FALSE),"") | C6: =IFERROR(VLOOKUP($H6,'QB Inv Curr'!$H:$AE,23,FALSE),"") | D6: =IFERROR(VLOOKUP($H6,'QB Inv Curr'!$H:$AL,29,FALSE),"") | E6: =IFERROR(SUM(B6/D6),"") | F6: =IFERROR(SUM(D6*12),"") | H6: 206LABEL | I6: Label | L6: 1 | M6: =VLOOKUP(H6,Inventory!A:L,12,FALSE) -> 0.31 | N6: =M6*L6 -> 0.31
B7: =IFERROR(VLOOKUP($H7,'QB Inv Curr'!$H:$AD,13,FALSE),"") | C7: =IFERROR(VLOOKUP($H7,'QB Inv Curr'!$H:$AE,23,FALSE),"") | D7: =IFERROR(VLOOKUP($H7,'QB Inv Curr'!$H:$AL,29,FALSE),"") | E7: =IFERROR(SUM(B7/D7),"") | F7: =IFERROR(SUM(D7*12),"") | H7: LABOR75 | I7: Labor | L7: 1 | M7: =VLOOKUP(H7,Inventory!A:L,12,FALSE) -> 0.75 | N7: =M7*L7 -> 0.75
B8: =IFERROR(VLOOKUP($H8,'QB Inv Curr'!$H:$AD,13,FALSE),"") | C8: =IFERROR(VLOOKUP($H8,'QB Inv Curr'!$H:$AE,23,FALSE),"") | D8: =IFERROR(VLOOKUP($H8,'QB Inv Curr'!$H:$AL,29,FALSE),"") | E8: =IFERROR(SUM(B8/D8),"") | F8: =IFERROR(SUM(D8*12),"") | I8: Box | L8: 0.25 | M8: 0.9 | N8: =M8*L8 -> 0.225
B9: =IFERROR(VLOOKUP($H9,'QB Inv Curr'!$H:$AD,13,FALSE),"") | C9: =IFERROR(VLOOKUP($H9,'QB Inv Curr'!$H:$AE,23,FALSE),"") | D9: =IFERROR(VLOOKUP($H9,'QB Inv Curr'!$H:$AL,29,FALSE),"") | E9: =IFERROR(SUM(B9/D9),"") | F9: =IFERROR(SUM(D9*12),"")
A10: 11-855 | B10: =IFERROR(VLOOKUP($H10,'QB Inv Curr'!$H:$AD,13,FALSE),"") -> 0 | C10: =IFERROR(VLOOKUP($H10,'QB Inv Curr'!$H:$AE,23,FALSE),"") -> 0 | D10: =IFERROR(VLOOKUP($H10,'QB Inv Curr'!$H:$AL,29,FALSE),"") -> 0 | E10: =IFERROR(SUM(B10/D10),"") | F10: =IFERROR(SUM(D10*12),"") -> 0 | G10: K-DL-150-03 | H10: 11-855 | J10: GENUINE AXLETEK 2K 1.50” I.D. Double Lip Seal PAK/2 DL-150-03 | K10: 810797031404 | L10: 1 | Q10: =SUM(N11:N15) -> 2.529 | R10: 4.72 | S10: 8.99 | W10: =Q10*1.75 -> 4.42575 | X10: =SUM(W10-Q10)/W10 -> 0.42857143 | Y10: 6.99 | Z10: =SUM(Y10-W10)/Y10 -> 0.36684549 | AA10: 6.95 | AB10: =SUM(AA10-Q10)/AA10 -> 0.63611511 | AC10: https://www.etrailer.com/Trailer-Bearings-Races-Seals-Caps/TruRyde/RG06-020.html
A11: 12-860 | B11: =IFERROR(VLOOKUP($H11,'QB Inv Curr'!$H:$AD,13,FALSE),"") -> 1000 | C11: =IFERROR(VLOOKUP($H11,'QB Inv Curr'!$H:$AE,23,FALSE),"") -> 0 | D11: =IFERROR(VLOOKUP($H11,'QB Inv Curr'!$H:$AL,29,FALSE),"") -> 0 | E11: =IFERROR(SUM(B11/D11),"") | F11: =IFERROR(SUM(D11*12),"") -> 0 | G11: DL-150-03 | H11: 12-860 | I11: 2) Grease Seal 1.50" ID (DL-150-03) | L11: 2 | M11: =VLOOKUP(H11,Inventory!A:L,12,FALSE) -> 0.28 | N11: =SUM(M11*$N$2)*L11 -> 0.644 | AA11: 8.95 | AC11: https://www.lippert.com/lippert-double-lip-grease-seal-2200-lb-brake-idler-hub-assemblies-15in-id-2-pack-2023134653-2023134653?queryID=094563ed1bc9f91f4fc64f2d35287416&objectID=23851&indexName=gwp_d2c_prod_lippert_products
B12: =IFERROR(VLOOKUP($H12,'QB Inv Curr'!$H:$AD,13,FALSE),"") -> 880 | C12: =IFERROR(VLOOKUP($H12,'QB Inv Curr'!$H:$AE,23,FALSE),"") -> 0 | D12: =IFERROR(VLOOKUP($H12,'QB Inv Curr'!$H:$AL,29,FALSE),"") -> 0 | E12: =IFERROR(SUM(B12/D12),"") | F12: =IFERROR(SUM(D12*12),"") -> 0 | H12: 206TF | I12: Clam | L12: 1 | M12: =VLOOKUP(H12,Inventory!A:L,12,FALSE) -> 0.6 | N12: =M12*L12 -> 0.6
A13: 2023134653 | B13: =IFERROR(VLOOKUP($H13,'QB Inv Curr'!$H:$AD,13,FALSE),"") | C13: =IFERROR(VLOOKUP($H13,'QB Inv Curr'!$H:$AE,23,FALSE),"") | D13: =IFERROR(VLOOKUP($H13,'QB Inv Curr'!$H:$AL,29,FALSE),"") | E13: =IFERROR(SUM(B13/D13),"") | F13: =IFERROR(SUM(D13*12),"") | H13: 206LABEL | I13: Label | L13: 1 | M13: =VLOOKUP(H13,Inventory!A:L,12,FALSE) -> 0.31 | N13: =M13*L13 -> 0.31
A14: RG06-020 | B14: =IFERROR(VLOOKUP($H14,'QB Inv Curr'!$H:$AD,13,FALSE),"") | C14: =IFERROR(VLOOKUP($H14,'QB Inv Curr'!$H:$AE,23,FALSE),"") | D14: =IFERROR(VLOOKUP($H14,'QB Inv Curr'!$H:$AL,29,FALSE),"") | E14: =IFERROR(SUM(B14/D14),"") | F14: =IFERROR(SUM(D14*12),"") | G14: 206TF | H14: LABOR75 | I14: Labor | L14: 1 | M14: =VLOOKUP(H14,Inventory!A:L,12,FALSE) -> 0.75 | N14: =M14*L14 -> 0.75
B15: =IFERROR(VLOOKUP($H15,'QB Inv Curr'!$H:$AD,13,FALSE),"") | C15: =IFERROR(VLOOKUP($H15,'QB Inv Curr'!$H:$AE,23,FALSE),"") | D15: =IFERROR(VLOOKUP($H15,'QB Inv Curr'!$H:$AL,29,FALSE),"") | E15: =IFERROR(SUM(B15/D15),"") | F15: =IFERROR(SUM(D15*12),"") | I15: Box | L15: 0.25 | M15: 0.9 | N15: =M15*L15 -> 0.225
